2025-08-21 15:55:00 [ERROR] app - Monitoring API error
Traceback (most recent call last):
  File "/var/www/WIFI-ADMIN/venv/lib/python3.10/site-packages/sqlalchemy/engine/base.py", line 1967, in _exec_single_context
    self.dialect.do_execute(
  File "/var/www/WIFI-ADMIN/venv/lib/python3.10/site-packages/sqlalchemy/engine/default.py", line 951, in do_execute
    cursor.execute(statement, parameters)
  File "/var/www/WIFI-ADMIN/venv/lib/python3.10/site-packages/pymysql/cursors.py", line 153, in execute
    result = self._query(query)
  File "/var/www/WIFI-ADMIN/venv/lib/python3.10/site-packages/pymysql/cursors.py", line 322, in _query
    conn.query(q)
  File "/var/www/WIFI-ADMIN/venv/lib/python3.10/site-packages/pymysql/connections.py", line 563, in query
    self._affected_rows = self._read_query_result(unbuffered=unbuffered)
  File "/var/www/WIFI-ADMIN/venv/lib/python3.10/site-packages/pymysql/connections.py", line 825, in _read_query_result
    result.read()
  File "/var/www/WIFI-ADMIN/venv/lib/python3.10/site-packages/pymysql/connections.py", line 1199, in read
    first_packet = self.connection._read_packet()
  File "/var/www/WIFI-ADMIN/venv/lib/python3.10/site-packages/pymysql/connections.py", line 744, in _read_packet
    packet_header = self._read_bytes(4)
  File "/var/www/WIFI-ADMIN/venv/lib/python3.10/site-packages/pymysql/connections.py", line 798, in _read_bytes
    raise err.OperationalError(
pymysql.err.OperationalError: (2013, 'Lost connection to MySQL server during query')

The above exception was the direct cause of the following exception:

Traceback (most recent call last):
  File "/var/www/WIFI-ADMIN/app/blueprints/monitoring/routes.py", line 88, in api_monitoring
    .all()
  File "/var/www/WIFI-ADMIN/venv/lib/python3.10/site-packages/sqlalchemy/orm/query.py", line 2704, in all
    return self._iter().all()  # type: ignore
  File "/var/www/WIFI-ADMIN/venv/lib/python3.10/site-packages/sqlalchemy/orm/query.py", line 2857, in _iter
    result: Union[ScalarResult[_T], Result[_T]] = self.session.execute(
  File "/var/www/WIFI-ADMIN/venv/lib/python3.10/site-packages/sqlalchemy/orm/session.py", line 2365, in execute
    return self._execute_internal(
  File "/var/www/WIFI-ADMIN/venv/lib/python3.10/site-packages/sqlalchemy/orm/session.py", line 2251, in _execute_internal
    result: Result[Any] = compile_state_cls.orm_execute_statement(
  File "/var/www/WIFI-ADMIN/venv/lib/python3.10/site-packages/sqlalchemy/orm/context.py", line 306, in orm_execute_statement
    result = conn.execute(
  File "/var/www/WIFI-ADMIN/venv/lib/python3.10/site-packages/sqlalchemy/engine/base.py", line 1419, in execute
    return meth(
  File "/var/www/WIFI-ADMIN/venv/lib/python3.10/site-packages/sqlalchemy/sql/elements.py", line 526, in _execute_on_connection
    return connection._execute_clauseelement(
  File "/var/www/WIFI-ADMIN/venv/lib/python3.10/site-packages/sqlalchemy/engine/base.py", line 1641, in _execute_clauseelement
    ret = self._execute_context(
  File "/var/www/WIFI-ADMIN/venv/lib/python3.10/site-packages/sqlalchemy/engine/base.py", line 1846, in _execute_context
    return self._exec_single_context(
  File "/var/www/WIFI-ADMIN/venv/lib/python3.10/site-packages/sqlalchemy/engine/base.py", line 1986, in _exec_single_context
    self._handle_dbapi_exception(
  File "/var/www/WIFI-ADMIN/venv/lib/python3.10/site-packages/sqlalchemy/engine/base.py", line 2355, in _handle_dbapi_exception
    raise sqlalchemy_exception.with_traceback(exc_info[2]) from e
  File "/var/www/WIFI-ADMIN/venv/lib/python3.10/site-packages/sqlalchemy/engine/base.py", line 1967, in _exec_single_context
    self.dialect.do_execute(
  File "/var/www/WIFI-ADMIN/venv/lib/python3.10/site-packages/sqlalchemy/engine/default.py", line 951, in do_execute
    cursor.execute(statement, parameters)
  File "/var/www/WIFI-ADMIN/venv/lib/python3.10/site-packages/pymysql/cursors.py", line 153, in execute
    result = self._query(query)
  File "/var/www/WIFI-ADMIN/venv/lib/python3.10/site-packages/pymysql/cursors.py", line 322, in _query
    conn.query(q)
  File "/var/www/WIFI-ADMIN/venv/lib/python3.10/site-packages/pymysql/connections.py", line 563, in query
    self._affected_rows = self._read_query_result(unbuffered=unbuffered)
  File "/var/www/WIFI-ADMIN/venv/lib/python3.10/site-packages/pymysql/connections.py", line 825, in _read_query_result
    result.read()
  File "/var/www/WIFI-ADMIN/venv/lib/python3.10/site-packages/pymysql/connections.py", line 1199, in read
    first_packet = self.connection._read_packet()
  File "/var/www/WIFI-ADMIN/venv/lib/python3.10/site-packages/pymysql/connections.py", line 744, in _read_packet
    packet_header = self._read_bytes(4)
  File "/var/www/WIFI-ADMIN/venv/lib/python3.10/site-packages/pymysql/connections.py", line 798, in _read_bytes
    raise err.OperationalError(
sqlalchemy.exc.OperationalError: (pymysql.err.OperationalError) (2013, 'Lost connection to MySQL server during query')
[SQL: SELECT user.`MAC` AS `user_MAC`, user.fio AS user_fio, user.phone_number AS user_phone_number 
FROM user 
WHERE upper(user.`MAC`) IN (%(upper_1_1)s, %(upper_1_2)s)]
[parameters: {'upper_1_1': '7C:B5:66:D7:FC:4E', 'upper_1_2': '2E:45:36:C2:C8:D2'}]
(Background on this error at: https://sqlalche.me/e/20/e3q8)
2025-08-21 15:58:08 [ERROR] app - Monitoring API error
Traceback (most recent call last):
  File "/var/www/WIFI-ADMIN/venv/lib/python3.10/site-packages/sqlalchemy/engine/base.py", line 1967, in _exec_single_context
    self.dialect.do_execute(
  File "/var/www/WIFI-ADMIN/venv/lib/python3.10/site-packages/sqlalchemy/engine/default.py", line 951, in do_execute
    cursor.execute(statement, parameters)
  File "/var/www/WIFI-ADMIN/venv/lib/python3.10/site-packages/pymysql/cursors.py", line 153, in execute
    result = self._query(query)
  File "/var/www/WIFI-ADMIN/venv/lib/python3.10/site-packages/pymysql/cursors.py", line 322, in _query
    conn.query(q)
  File "/var/www/WIFI-ADMIN/venv/lib/python3.10/site-packages/pymysql/connections.py", line 563, in query
    self._affected_rows = self._read_query_result(unbuffered=unbuffered)
  File "/var/www/WIFI-ADMIN/venv/lib/python3.10/site-packages/pymysql/connections.py", line 825, in _read_query_result
    result.read()
  File "/var/www/WIFI-ADMIN/venv/lib/python3.10/site-packages/pymysql/connections.py", line 1199, in read
    first_packet = self.connection._read_packet()
  File "/var/www/WIFI-ADMIN/venv/lib/python3.10/site-packages/pymysql/connections.py", line 775, in _read_packet
    packet.raise_for_error()
  File "/var/www/WIFI-ADMIN/venv/lib/python3.10/site-packages/pymysql/protocol.py", line 219, in raise_for_error
    err.raise_mysql_exception(self._data)
  File "/var/www/WIFI-ADMIN/venv/lib/python3.10/site-packages/pymysql/err.py", line 150, in raise_mysql_exception
    raise errorclass(errno, errval)
pymysql.err.ProgrammingError: (1146, "Table 'zeekdb.user' doesn't exist")

The above exception was the direct cause of the following exception:

Traceback (most recent call last):
  File "/var/www/WIFI-ADMIN/app/blueprints/monitoring/routes.py", line 72, in api_monitoring
    rows = conn.execute(data_sql, params).mappings().all()
  File "/var/www/WIFI-ADMIN/venv/lib/python3.10/site-packages/sqlalchemy/engine/base.py", line 1419, in execute
    return meth(
  File "/var/www/WIFI-ADMIN/venv/lib/python3.10/site-packages/sqlalchemy/sql/elements.py", line 526, in _execute_on_connection
    return connection._execute_clauseelement(
  File "/var/www/WIFI-ADMIN/venv/lib/python3.10/site-packages/sqlalchemy/engine/base.py", line 1641, in _execute_clauseelement
    ret = self._execute_context(
  File "/var/www/WIFI-ADMIN/venv/lib/python3.10/site-packages/sqlalchemy/engine/base.py", line 1846, in _execute_context
    return self._exec_single_context(
  File "/var/www/WIFI-ADMIN/venv/lib/python3.10/site-packages/sqlalchemy/engine/base.py", line 1986, in _exec_single_context
    self._handle_dbapi_exception(
  File "/var/www/WIFI-ADMIN/venv/lib/python3.10/site-packages/sqlalchemy/engine/base.py", line 2355, in _handle_dbapi_exception
    raise sqlalchemy_exception.with_traceback(exc_info[2]) from e
  File "/var/www/WIFI-ADMIN/venv/lib/python3.10/site-packages/sqlalchemy/engine/base.py", line 1967, in _exec_single_context
    self.dialect.do_execute(
  File "/var/www/WIFI-ADMIN/venv/lib/python3.10/site-packages/sqlalchemy/engine/default.py", line 951, in do_execute
    cursor.execute(statement, parameters)
  File "/var/www/WIFI-ADMIN/venv/lib/python3.10/site-packages/pymysql/cursors.py", line 153, in execute
    result = self._query(query)
  File "/var/www/WIFI-ADMIN/venv/lib/python3.10/site-packages/pymysql/cursors.py", line 322, in _query
    conn.query(q)
  File "/var/www/WIFI-ADMIN/venv/lib/python3.10/site-packages/pymysql/connections.py", line 563, in query
    self._affected_rows = self._read_query_result(unbuffered=unbuffered)
  File "/var/www/WIFI-ADMIN/venv/lib/python3.10/site-packages/pymysql/connections.py", line 825, in _read_query_result
    result.read()
  File "/var/www/WIFI-ADMIN/venv/lib/python3.10/site-packages/pymysql/connections.py", line 1199, in read
    first_packet = self.connection._read_packet()
  File "/var/www/WIFI-ADMIN/venv/lib/python3.10/site-packages/pymysql/connections.py", line 775, in _read_packet
    packet.raise_for_error()
  File "/var/www/WIFI-ADMIN/venv/lib/python3.10/site-packages/pymysql/protocol.py", line 219, in raise_for_error
    err.raise_mysql_exception(self._data)
  File "/var/www/WIFI-ADMIN/venv/lib/python3.10/site-packages/pymysql/err.py", line 150, in raise_mysql_exception
    raise errorclass(errno, errval)
sqlalchemy.exc.ProgrammingError: (pymysql.err.ProgrammingError) (1146, "Table 'zeekdb.user' doesn't exist")
[SQL: 
                SELECT
                    m.id,
                    DATE_FORMAT(m.ts, '%%Y-%%m-%%d %%H:%%i:%%s') AS ts,
                    m.client_ip,
                    UPPER(m.mac) AS mac,
                    m.hostname,
                    m.domain,
                    m.protocol,
                    u.fio,
                    u.phone_number
                FROM monitoring m
                LEFT JOIN user u ON UPPER(m.mac) = UPPER(u.MAC)
                
                ORDER BY id DESC
                LIMIT %(limit)s OFFSET %(offset)s
            ]
[parameters: {'limit': 20, 'offset': 0}]
(Background on this error at: https://sqlalche.me/e/20/f405)
